<mujoco model="ur10">

    <option>
        <flag gravity="disable"/>
    </option>
    
    <compiler angle="radian" />
    <size njmax="500" nconmax="100" />
    <asset>
        <mesh name="base" file="base.stl" />
        <mesh name="shoulder" file="shoulder.stl" />
        <mesh name="upperarm" file="upperarm.stl" />
        <mesh name="forearm" file="forearm.stl" />
        <mesh name="wrist1" file="wrist1.stl" />
        <mesh name="wrist2" file="wrist2.stl" />
        <mesh name="wrist3" file="wrist3.stl" />
        <material name="RobMat" specular="0.9" shininess="0.5" reflectance="0" rgba="0.7 0.7 0.7 1" emission="0.1" />
        <material name="GriMat" specular="0.9" shininess="0.5" reflectance="0" rgba="0.1 0.1 0.1 1" emission="0.1" />
        <material name="BasketMat" specular="0" shininess="0" reflectance="0" rgba="0.26 0.16 0.16796875 1" emission="0" />
        <material name="Light" specular="0" shininess="0.6" reflectance="0.9" rgba="0.5 0.5 1 1" emission="0.7" />
        <material name="bench_mat"  shininess="0.1" specular="0.5" reflectance="0.2"/>
    </asset>
    <worldbody>
 
        <camera name="c1" mode="fixed"  pos="0 -2 2.4" axisangle="2 0 0 1"/>
        <camera name="c2" mode="fixed"  pos="0 -2.5 2.5" axisangle="2 0 0 1"/>
        <camera name="c3" mode="fixed"  pos="0 -3 3" axisangle="2 0 0 1"/>

        <light directional="false" castshadow="false" pos="-0.5 0.5 3" dir="0 0 -1" />
        <light directional="false" castshadow="false"pos="-0.5 0.5 1.5" dir="0 -1 0" />
        <geom name="floor" pos="0 0 -0.4" size="20 20 1" type="plane" rgba="0.7 0.7 0.7 1" material="BasketMat" />
        <body name="box_link" pos="0 0 0">
            <!--<geom size=".3 .2 .435" type="box" material="bench_mat"/>-->
            <geom size=".18 .18 .03" pos ="0 0 -0.015" type="box" material="bench_mat"/>
            <geom size=".03 .03 0.2" pos ="0.15 0.15 -0.2" type="box" material="bench_mat"/>
            <geom size=".03 .03 0.2" pos ="-0.15 0.15 -0.2" type="box" material="bench_mat"/>
            <geom size=".03 .03 0.2" pos ="0.15 -0.15 -0.2" type="box" material="bench_mat"/>
            <geom size=".03 .03 0.2" pos ="-0.15 -0.15 -0.2" type="box" material="bench_mat"/>
            <inertial pos="0 0 0" mass="1000" diaginertia="0 0 0" />


		<body name="base_link" pos="0 0 0">
		    <inertial pos="0 0 0" quat="0.5 0.5 -0.5 0.5" mass="4" diaginertia="0.005625 0.00305317 0.00305317" />
		    <geom name="base_mesh" type="mesh" mesh="base" material="RobMat" />
		    <geom name="base_cap" type="cylinder" pos="0 0 0.222" size="0.0758 0.02" rgba="0.596 0.96 1 1" material="RobMat" contype="0" conaffinity="0" />

		    <body name="shoulder_link" pos="0 0 0.1273">
		        <inertial pos="0 0 0" mass="3.7" diaginertia="0.00809316 0.00809316 0.005625" />
		        <joint name="shoulder_pan_joint" pos="0 0 0" axis="0 0 1" limited="true" range="-6.28319 6.28319" />
		        <geom name="shoulder_mesh" type="mesh" mesh="shoulder" material="RobMat" />
		        <geom name="shoulder_cap" type="cylinder" pos="0 0.266 0" quat="0.707107 0.707107 0 0" size="0.0758 0.02" rgba="0.596 0.96 1 1" material="RobMat" contype="0" conaffinity="0" />
		        <site name="frame-ee-1" pos="0 0 0" rgba=".9 .0 .9 1" size="0.008"/>

		        <body name="upper_arm_link" pos="0 0.220941 0" quat="0.707107 0 0.707107 0">
		            <inertial pos="0 0 0.121825" mass="8.393" diaginertia="0.0217285 0.0217285 0.00961875" />
		            <joint name="shoulder_lift_joint" pos="0 0 0" axis="0 1 0" limited="true" range="-6.28319 6.28319" />
		            <geom name="upperarm_mesh" type="mesh" mesh="upperarm" material="RobMat" />
		            
		            <site name="frame-ee-2" pos="0 0 0" rgba=".9 .0 .9 1" size="0.008"/>

		            <body name="forearm_link" pos="0 -0.1719 0.612">
		                <inertial pos="0 0 0.106625" mass="2.275" diaginertia="0.00654681 0.00654681 0.00354375" />
		                <joint name="elbow_joint" pos="0 0 0" axis="0 1 0" limited="true" range="-3.14159 3.14159" />
		                <geom name="forearm_mesh" type="mesh" mesh="forearm" material="RobMat" />
		                <geom name="forearm_cap" type="cylinder" pos="0 0.1925 0" quat="0.707107 0.707107 0 0" size="0.064 0.02" rgba="0.596 0.96 1 1" material="RobMat" contype="0" conaffinity="0" />
		                <site name="frame-ee-3" pos="0 0 0" rgba=".9 .0 .9 1" size="0.008"/>

		                <body name="wrist_1_link" pos="0 0 0.5723" quat="0.707107 0 0.707107 0">
		                    <inertial pos="0 0 0" quat="0.5 0.5 -0.5 0.5" mass="1.219" diaginertia="0.00225 0.002085 0.002085" />
		                    <joint name="wrist_1_joint" pos="0 0 0" axis="0 1 0" limited="true" range="-6.28319 6.28319" />
		                    <geom name="wrist1_mesh" type="mesh" mesh="wrist1" material="RobMat" />
		                    <geom name="wrist1_cap" type="cylinder" pos="0 -0.0525 0" quat="0.707107 0.707107 0 0" size="0.049 0.015" rgba="0.596 0.96 1 1" material="RobMat" contype="0" conaffinity="0" />
		                    <site name="frame-ee-4" pos="0 0 0" rgba=".9 .0 .9 1" size="0.008"/>

		                    <body name="wrist_2_link" pos="0 0.1149 0">
		                        <inertial pos="0 0 0" quat="0.5 0.5 -0.5 0.5" mass="1.219" diaginertia="0.00225 0.002085 0.002085" />
		                        <joint name="wrist_2_joint" pos="0 0 0" axis="0 0 1" limited="true" range="-6.28319 6.28319" />
		                        <geom name="wrist2_mesh" type="mesh" mesh="wrist2" material="RobMat" />
		                        <geom name="wrist2_cap" type="cylinder" pos="0 0 -0.0525" quat="0.707107 0 0 0.707107" size="0.049 0.015" rgba="0.596 0.96 1 1" material="RobMat" contype="0" conaffinity="0" />
		           
		                        <site name="frame-ee-5" pos="0 0 0" rgba=".9 .0 .9 1" size="0.008"/>

		                        <body name="wrist_3_link" pos="0 0 0.1157">
		                            <inertial pos="0 0 0" quat="0.5 0.5 -0.5 0.5" mass="0.1879" diaginertia="0.000984375 0.000912187 0.000912187" />
		                            <joint name="wrist_3_joint" pos="0 0 0" axis="0 1 0" limited="true" range="-6.28319 6.28319" />
		                            <geom name="wrist3_mesh" type="mesh" mesh="wrist3" material="RobMat" contype="1" conaffinity="1" />
		                            <geom name="wrist3_cap" type="cylinder" pos="0 -0.0525 0" quat="0.707107 0.707107 0 0" size="0.049 0.015" rgba="0.596 0.96 1 1" material="RobMat" contype="0" conaffinity="0" />
		                            <body name="ee_link" pos="0 0.0819 0" quat="0.707107 0 0 0.707107">

		                                <!-- <site pos="0.1 0 0" rgba=".9 .0 .0 1" size="0.025"/>
		                                <site pos="0 0.1 0" rgba=".0 .9 .0 1" size="0.025"/>
		                                <site pos="0 0 0.1" rgba=".0 .0 .9 1" size="0.025"/>

		                                <site name="frame-ee-1" pos="-0.0175 0 0.035" rgba=".9 .0 .9 1" size="0.0025"/> -->


		                                <inertial pos="-0.01 0 0" mass="0.001" diaginertia="1.66667e-08 1.66667e-08 1.66667e-08" />
		                                <geom size="0.005 0.005 0.005" pos="-0.01 0 0" type="box" />

		                                <site name="frame-ee-6" pos="0 0 0" rgba=".9 .0 .9 1" size="0.025"/>

		                            </body>
		                            <body name="tool0" pos="0 0.0819 0" quat="0.707107 -0.707107 0 0">
		                                <inertial pos="0 0.0819 0" quat="0.707107 -0.707107 0 0" mass="0" diaginertia="0 0 0" />
		                            </body>
		                        </body>
		                    </body>
		                </body>
		            </body>
		        </body>
		    </body>
		    <body name="base" pos="0 0 0" quat="1.7949e-09 0 0 -1">
		        <inertial pos="0 0 0" quat="1.7949e-09 0 0 -1" mass="0" diaginertia="0 0 0" />
		    </body>
		 <body name="target_body_1" pos="0 0 0">
		    <geom name="target_1" pos="0 0 0" size="0.03" rgba="0.9529411765 0 0. 1" />
		    <site name="target_site_1" pos="0 0 0" size="0.03"  rgba="0.9529411765 0 0 1" />
		    <joint name="free_x_1" pos="0 0 0" type="slide" axis="1 0 0" frictionloss="0" damping="0" />
		    <joint name="free_y_1" pos="0 0 0" type="slide" axis="0 1 0" frictionloss="0" damping="0" />
		    <joint name="free_z_1" pos="0 0 0" type="slide" axis="0 0 1" frictionloss="0" damping="0" />
		    <joint name="free_ball_1" pos="0 0 0" type="ball" frictionloss="0" damping="0" />
		    
		</body>             
		</body>
        

        </body>
    </worldbody>
    <sensor>
        <framepos objname="frame-ee-1" objtype="site"/>
        <framepos objname="frame-ee-2" objtype="site"/>
        <framepos objname="frame-ee-3" objtype="site"/>
        <framepos objname="frame-ee-4" objtype="site"/>
        <framepos objname="frame-ee-5" objtype="site"/>
        <framepos objname="frame-ee-6" objtype="site"/>

    </sensor>
</mujoco>
